<mujoco model="spot">
  <compiler angle="radian" />
  <asset>
    <mesh name="mainbody" file="stl/mainbody.stl" scale="0.001 0.001 0.001" />
    <mesh name="frontpart" file="stl/frontpart.stl" scale="0.001 0.001 0.001" />
    <mesh name="backpart" file="stl/backpart.stl" scale="0.001 0.001 0.001" />
    <mesh name="lshoulder" file="stl/lshoulder.stl" scale="0.001 0.001 0.001" />
    <mesh name="larm_cover" file="stl/larm_cover.stl" scale="0.001 0.001 0.001" />
    <mesh name="larm" file="stl/larm.stl" scale="0.001 0.001 0.001" />
    <mesh name="lfoot" file="stl/lfoot.stl" scale="0.001 0.001 0.001" />
    <mesh name="foot" file="stl/foot.stl" scale="0.001 0.001 0.001" />
    <mesh name="rshoulder" file="stl/rshoulder.stl" scale="0.001 0.001 0.001" />
    <mesh name="rarm_cover" file="stl/rarm_cover.stl" scale="0.001 0.001 0.001" />
    <mesh name="rarm" file="stl/rarm.stl" scale="0.001 0.001 0.001" />
    <mesh name="rfoot" file="stl/rfoot.stl" scale="0.001 0.001 0.001" />
  </asset>

  <default>
    <geom density="0" type="mesh" friction="1.0 0.3 0.3" margin="0.001" quat="0 0 0 1" />

    <joint damping="0.01" armature="0.01" frictionloss="0.01" actuatorfrcrange="-100 100" />
  </default>

  <worldbody>
    <body name="base">
      <geom pos="0.045 0.06 -0.015" type="mesh" rgba="0.1 0.1 0.1 1"
        mesh="mainbody" mass="1.2" />
      <geom pos="0.04 0.06 -0.014" type="mesh" rgba="0.92 0.83 0 1"
        mesh="frontpart" mass="0.05" />
      <geom pos="0.04 0.06 -0.014" type="mesh" rgba="0.92 0.83 0 1" mesh="backpart"
        mass="0.05" />
      <site name="imu" pos="0 0 0" />
        
      <body name="front_left_shoulder_link" pos="0.093 .036 0">
        <joint name="motor_front_left_shoulder" pos="0 0 0" axis="1 0 0" range="-1 1"
          actuatorfrcrange="-100 100" />
        <geom mass="0.1" pos="0.135 0.02 -0.01"  type="mesh" rgba="0.1 0.1 0.1 1"
          mesh="lshoulder" />
        <body name="front_left_leg_link" pos="0 0.052 0">
          <joint name="motor_front_left_leg" pos="0 0 0" axis="0 1 0" range="-0.97 2.17"
            actuatorfrcrange="-100 100" />
          <geom mass="0.1" pos="0.125 -0.04 -0.02"  type="mesh" rgba="0.1 0.1 0.1 1"
            mesh="larm" />
          <geom pos="0.125 -0.04 -0.02"  type="mesh" rgba="0.92 0.83 0 1"
            mesh="larm_cover" />
          <body name="front_left_foot_link" pos="0.01 0 -0.12">
            <joint name="foot_motor_front_left" pos="0 0 0" axis="0 1 0" range="-2.59 0.1"
              actuatorfrcrange="-100 100" />
            <geom mass="0.105" pos="0.12 -0.04 0.1" type="mesh" rgba="0.1 0.1 0.1 1" mesh="lfoot" />
            <geom name="front_left_foot_mesh" pos="0 -0.01 -0.115" quat="0.980057 0 0.198718 0" type="mesh"
              rgba="0.6 0.6 0.6 1" mesh="foot" friction="10.0 0.3 0.3" />
          </body>
        </body>
      </body>
      <body name="front_right_shoulder_link" pos="0.093 -0.036 0">
        <joint name="motor_front_right_shoulder" pos="0 0 0" axis="1 0 0" range="-1 1" />
        <geom pos="0.135 0.09 -0.01"  type="mesh" mass="0.1" rgba="0.1 0.1 0.1 1"
          mesh="rshoulder" />
        <body name="front_right_leg_link" pos="0 -0.052 0">
          <joint name="motor_front_right_leg" pos="0 0 0" axis="0 1 0" range="-0.97 2.17"
            actuatorfrcrange="-100 100" />
          <geom pos="0.125 0.15 -0.02" mass="0.1" type="mesh" rgba="0.1 0.1 0.1 1" mesh="rarm" />
          <geom pos="0.125 0.15 -0.02" type="mesh" contype="0" rgba="0.92 0.83 0 1"
            mesh="rarm_cover" />
          <body name="front_right_foot_link" pos="0.01 0 -0.12">
            <joint name="foot_motor_front_right" pos="0 0 0" axis="0 1 0" range="-2.59 0.1" />
            <geom pos="0.12 0.15 0.1"  type="mesh" mass="0.105" rgba="0.1 0.1 0.1 1"
              mesh="rfoot" />
            <geom pos="0 -0.01 -0.115" quat="0.980057 0 0.198718 0" type="mesh"
              rgba="0.6 0.6 0.6 1" mesh="foot" friction="10.0 0.3 0.3" />
          </body>
        </body>
      </body>
      <body name="rear_left_shoulder_link" pos="-0.093 0.036 0">
        <joint name="motor_rear_left_shoulder" pos="0 0 0" axis="1 0 0" range="-1 1" />
        <geom mass="0.1" pos="0.135 0.02 -0.01"  type="mesh" rgba="0.1 0.1 0.1 1"
          mesh="lshoulder" />
        <body name="rear_left_leg_link" pos="0 0.052 0">
          <joint name="motor_rear_left_leg" pos="0 0 0" axis="0 1 0" range="-0.97 2.17" />
          <geom mass="0.1" pos="0.125 -0.04 -0.02"  type="mesh" rgba="0.1 0.1 0.1 1"
            mesh="larm" />
          <geom pos="0.125 -0.04 -0.02"  type="mesh" rgba="0.92 0.83 0 1"
            mesh="larm_cover" />
          <body name="rear_left_foot_link" pos="0.01 0 -0.12">
            <joint name="foot_motor_rear_left" pos="0 0 0" axis="0 1 0" range="-2.59 0.1" />
            <geom mass="0.105" pos="0.12 -0.04 0.1" type="mesh" rgba="0.1 0.1 0.1 1" mesh="lfoot" />
            <geom pos="0 -0.01 -0.115" quat="0.980057 0 0.198718 0" type="mesh"
              rgba="0.6 0.6 0.6 1" mesh="foot" friction="10.0 0.3 0.3" />
          </body>
        </body>
      </body>
      <body name="rear_right_shoulder_link" pos="-0.093 -0.036 0">
        <joint name="motor_rear_right_shoulder" pos="0 0 0" axis="1 0 0" range="-1 1" />
        <geom mass="0.1" pos="0.135 0.09 -0.01"  type="mesh" rgba="0.1 0.1 0.1 1"
          mesh="rshoulder" />
        <body name="rear_right_leg_link" pos="0 -0.052 0">
          <joint name="motor_rear_right_leg" pos="0 0 0" axis="0 1 0" range="-0.97 2.17" />
          <geom mass="0.1" pos="0.125 0.15 -0.02" type="mesh" rgba="0.1 0.1 0.1 1" mesh="rarm" />
          <geom pos="0.125 0.15 -0.02" type="mesh" contype="0" rgba="0.92 0.83 0 1"
            mesh="rarm_cover" />
          <body name="rear_right_foot_link" pos="0.01 0 -0.12">
            <joint name="foot_motor_rear_right" pos="0 0 0" axis="0 1 0" range="-2.59 0.1" />
            <geom mass="0.105" pos="0.12 0.15 0.1"  type="mesh" rgba="0.1 0.1 0.1 1"
              mesh="rfoot" />
            <geom pos="0 -0.01 -0.115" quat="0.980057 0 0.198718 0" type="mesh"
              rgba="0.6 0.6 0.6 1" mesh="foot" friction="10.0 0.3 0.3" />
          </body>
        </body>
      </body>
    </body>

  </worldbody>

  <contact>
    <exclude body1="base" body2="front_left_leg_link" />
    <exclude body1="base" body2="front_right_leg_link" />
    <exclude body1="base" body2="rear_left_leg_link" />
    <exclude body1="base" body2="rear_right_leg_link" />
  </contact>
  <sensor>
    <framequat name="imu_quat" objtype="site" objname="imu" />
    <gyro name="imu_gyro" site="imu" />
    <accelerometer name="imu_acc" site="imu" />
    <velocimeter name="imu_vel" site="imu" />
  </sensor>
</mujoco>